[2023-04-30T00:00:03.878+0000] {taskinstance.py:1090} INFO - Dependencies all met for dep_context=non-requeueable deps ti=<TaskInstance: user_processing.is_api_available scheduled__2023-04-29T00:00:00+00:00 [queued]>
[2023-04-30T00:00:03.890+0000] {taskinstance.py:1090} INFO - Dependencies all met for dep_context=requeueable deps ti=<TaskInstance: user_processing.is_api_available scheduled__2023-04-29T00:00:00+00:00 [queued]>
[2023-04-30T00:00:03.891+0000] {taskinstance.py:1288} INFO - 
--------------------------------------------------------------------------------
[2023-04-30T00:00:03.894+0000] {taskinstance.py:1289} INFO - Starting attempt 1 of 1
[2023-04-30T00:00:03.894+0000] {taskinstance.py:1290} INFO - 
--------------------------------------------------------------------------------
[2023-04-30T00:00:03.915+0000] {taskinstance.py:1309} INFO - Executing <Task(HttpSensor): is_api_available> on 2023-04-29 00:00:00+00:00
[2023-04-30T00:00:03.921+0000] {standard_task_runner.py:55} INFO - Started process 163098 to run task
[2023-04-30T00:00:03.924+0000] {standard_task_runner.py:82} INFO - Running: ['***', 'tasks', 'run', 'user_processing', 'is_api_available', 'scheduled__2023-04-29T00:00:00+00:00', '--job-id', '272', '--raw', '--subdir', 'DAGS_FOLDER/user_processing.py', '--cfg-path', '/tmp/tmpgw0ur962']
[2023-04-30T00:00:03.925+0000] {standard_task_runner.py:83} INFO - Job 272: Subtask is_api_available
[2023-04-30T00:00:04.003+0000] {task_command.py:389} INFO - Running <TaskInstance: user_processing.is_api_available scheduled__2023-04-29T00:00:00+00:00 [running]> on host 1f05588790e0
[2023-04-30T00:00:04.107+0000] {taskinstance.py:1518} INFO - Exporting the following env vars:
AIRFLOW_CTX_DAG_OWNER=***
AIRFLOW_CTX_DAG_ID=user_processing
AIRFLOW_CTX_TASK_ID=is_api_available
AIRFLOW_CTX_EXECUTION_DATE=2023-04-29T00:00:00+00:00
AIRFLOW_CTX_TRY_NUMBER=1
AIRFLOW_CTX_DAG_RUN_ID=scheduled__2023-04-29T00:00:00+00:00
[2023-04-30T00:00:04.111+0000] {http.py:122} INFO - Poking: https://randomuser.me/
[2023-04-30T00:00:04.124+0000] {base.py:73} INFO - Using connection ID 'user_api' for task execution.
[2023-04-30T00:00:04.670+0000] {http.py:170} ERROR - HTTP error: Not Found
[2023-04-30T00:00:04.671+0000] {http.py:171} ERROR - Not Found
[2023-04-30T00:01:04.732+0000] {http.py:122} INFO - Poking: https://randomuser.me/
[2023-04-30T00:01:04.739+0000] {base.py:73} INFO - Using connection ID 'user_api' for task execution.
[2023-04-30T00:01:05.193+0000] {http.py:170} ERROR - HTTP error: Not Found
[2023-04-30T00:01:05.194+0000] {http.py:171} ERROR - Not Found
[2023-04-30T00:02:05.241+0000] {http.py:122} INFO - Poking: https://randomuser.me/
[2023-04-30T00:02:05.251+0000] {base.py:73} INFO - Using connection ID 'user_api' for task execution.
[2023-04-30T00:02:05.745+0000] {http.py:170} ERROR - HTTP error: Not Found
[2023-04-30T00:02:05.745+0000] {http.py:171} ERROR - Not Found
[2023-04-30T00:03:05.805+0000] {http.py:122} INFO - Poking: https://randomuser.me/
[2023-04-30T00:03:05.813+0000] {base.py:73} INFO - Using connection ID 'user_api' for task execution.
[2023-04-30T00:03:06.296+0000] {http.py:170} ERROR - HTTP error: Not Found
[2023-04-30T00:03:06.296+0000] {http.py:171} ERROR - Not Found
[2023-04-30T00:04:06.358+0000] {http.py:122} INFO - Poking: https://randomuser.me/
[2023-04-30T00:04:06.367+0000] {base.py:73} INFO - Using connection ID 'user_api' for task execution.
[2023-04-30T00:04:06.810+0000] {http.py:170} ERROR - HTTP error: Not Found
[2023-04-30T00:04:06.811+0000] {http.py:171} ERROR - Not Found
[2023-04-30T00:05:06.873+0000] {http.py:122} INFO - Poking: https://randomuser.me/
[2023-04-30T00:05:06.882+0000] {base.py:73} INFO - Using connection ID 'user_api' for task execution.
[2023-04-30T00:05:07.333+0000] {http.py:170} ERROR - HTTP error: Not Found
[2023-04-30T00:05:07.334+0000] {http.py:171} ERROR - Not Found
[2023-04-30T00:06:07.397+0000] {http.py:122} INFO - Poking: https://randomuser.me/
[2023-04-30T00:06:07.405+0000] {base.py:73} INFO - Using connection ID 'user_api' for task execution.
[2023-04-30T00:06:07.905+0000] {http.py:170} ERROR - HTTP error: Not Found
[2023-04-30T00:06:07.905+0000] {http.py:171} ERROR - Not Found
[2023-04-30T00:07:07.967+0000] {http.py:122} INFO - Poking: https://randomuser.me/
[2023-04-30T00:07:07.977+0000] {base.py:73} INFO - Using connection ID 'user_api' for task execution.
[2023-04-30T00:07:08.471+0000] {http.py:170} ERROR - HTTP error: Not Found
[2023-04-30T00:07:08.472+0000] {http.py:171} ERROR - Not Found
[2023-04-30T00:08:08.532+0000] {http.py:122} INFO - Poking: https://randomuser.me/
[2023-04-30T00:08:08.545+0000] {base.py:73} INFO - Using connection ID 'user_api' for task execution.
[2023-04-30T00:08:08.995+0000] {http.py:170} ERROR - HTTP error: Not Found
[2023-04-30T00:08:08.995+0000] {http.py:171} ERROR - Not Found
[2023-04-30T00:09:09.058+0000] {http.py:122} INFO - Poking: https://randomuser.me/
[2023-04-30T00:09:09.066+0000] {base.py:73} INFO - Using connection ID 'user_api' for task execution.
[2023-04-30T00:09:09.517+0000] {http.py:170} ERROR - HTTP error: Not Found
[2023-04-30T00:09:09.517+0000] {http.py:171} ERROR - Not Found
[2023-04-30T00:10:09.576+0000] {http.py:122} INFO - Poking: https://randomuser.me/
[2023-04-30T00:10:09.584+0000] {base.py:73} INFO - Using connection ID 'user_api' for task execution.
[2023-04-30T00:10:10.094+0000] {http.py:170} ERROR - HTTP error: Not Found
[2023-04-30T00:10:10.094+0000] {http.py:171} ERROR - Not Found
[2023-04-30T00:11:10.156+0000] {http.py:122} INFO - Poking: https://randomuser.me/
[2023-04-30T00:11:10.163+0000] {base.py:73} INFO - Using connection ID 'user_api' for task execution.
[2023-04-30T00:11:10.594+0000] {http.py:170} ERROR - HTTP error: Not Found
[2023-04-30T00:11:10.594+0000] {http.py:171} ERROR - Not Found
[2023-04-30T00:12:10.645+0000] {http.py:122} INFO - Poking: https://randomuser.me/
[2023-04-30T00:12:10.653+0000] {base.py:73} INFO - Using connection ID 'user_api' for task execution.
[2023-04-30T00:12:11.142+0000] {http.py:170} ERROR - HTTP error: Not Found
[2023-04-30T00:12:11.143+0000] {http.py:171} ERROR - Not Found
[2023-04-30T00:13:11.204+0000] {http.py:122} INFO - Poking: https://randomuser.me/
[2023-04-30T00:13:11.213+0000] {base.py:73} INFO - Using connection ID 'user_api' for task execution.
[2023-04-30T00:13:11.702+0000] {http.py:170} ERROR - HTTP error: Not Found
[2023-04-30T00:13:11.703+0000] {http.py:171} ERROR - Not Found
[2023-04-30T00:14:11.764+0000] {http.py:122} INFO - Poking: https://randomuser.me/
[2023-04-30T00:14:11.774+0000] {base.py:73} INFO - Using connection ID 'user_api' for task execution.
[2023-04-30T00:14:12.207+0000] {http.py:170} ERROR - HTTP error: Not Found
[2023-04-30T00:14:12.207+0000] {http.py:171} ERROR - Not Found
[2023-04-30T00:15:12.228+0000] {http.py:122} INFO - Poking: https://randomuser.me/
[2023-04-30T00:15:12.237+0000] {base.py:73} INFO - Using connection ID 'user_api' for task execution.
[2023-04-30T00:15:12.728+0000] {http.py:170} ERROR - HTTP error: Not Found
[2023-04-30T00:15:12.729+0000] {http.py:171} ERROR - Not Found
[2023-04-30T00:16:12.788+0000] {http.py:122} INFO - Poking: https://randomuser.me/
[2023-04-30T00:16:12.796+0000] {base.py:73} INFO - Using connection ID 'user_api' for task execution.
[2023-04-30T00:16:13.241+0000] {http.py:170} ERROR - HTTP error: Not Found
[2023-04-30T00:16:13.241+0000] {http.py:171} ERROR - Not Found
[2023-04-30T00:17:13.300+0000] {http.py:122} INFO - Poking: https://randomuser.me/
[2023-04-30T00:17:13.307+0000] {base.py:73} INFO - Using connection ID 'user_api' for task execution.
[2023-04-30T00:17:13.744+0000] {http.py:170} ERROR - HTTP error: Not Found
[2023-04-30T00:17:13.744+0000] {http.py:171} ERROR - Not Found
[2023-04-30T00:18:13.805+0000] {http.py:122} INFO - Poking: https://randomuser.me/
[2023-04-30T00:18:13.813+0000] {base.py:73} INFO - Using connection ID 'user_api' for task execution.
[2023-04-30T00:18:14.269+0000] {http.py:170} ERROR - HTTP error: Not Found
[2023-04-30T00:18:14.269+0000] {http.py:171} ERROR - Not Found
[2023-04-30T00:19:14.332+0000] {http.py:122} INFO - Poking: https://randomuser.me/
[2023-04-30T00:19:14.343+0000] {base.py:73} INFO - Using connection ID 'user_api' for task execution.
[2023-04-30T00:19:14.781+0000] {http.py:170} ERROR - HTTP error: Not Found
[2023-04-30T00:19:14.782+0000] {http.py:171} ERROR - Not Found
[2023-04-30T00:20:14.844+0000] {http.py:122} INFO - Poking: https://randomuser.me/
[2023-04-30T00:20:14.853+0000] {base.py:73} INFO - Using connection ID 'user_api' for task execution.
[2023-04-30T00:20:15.378+0000] {http.py:170} ERROR - HTTP error: Not Found
[2023-04-30T00:20:15.378+0000] {http.py:171} ERROR - Not Found
[2023-04-30T00:21:15.440+0000] {http.py:122} INFO - Poking: https://randomuser.me/
[2023-04-30T00:21:15.459+0000] {base.py:73} INFO - Using connection ID 'user_api' for task execution.
[2023-04-30T00:21:15.958+0000] {http.py:170} ERROR - HTTP error: Not Found
[2023-04-30T00:21:15.958+0000] {http.py:171} ERROR - Not Found
[2023-04-30T00:22:16.016+0000] {http.py:122} INFO - Poking: https://randomuser.me/
[2023-04-30T00:22:16.026+0000] {base.py:73} INFO - Using connection ID 'user_api' for task execution.
[2023-04-30T00:22:16.465+0000] {http.py:170} ERROR - HTTP error: Not Found
[2023-04-30T00:22:16.465+0000] {http.py:171} ERROR - Not Found
[2023-04-30T00:23:16.517+0000] {http.py:122} INFO - Poking: https://randomuser.me/
[2023-04-30T00:23:16.526+0000] {base.py:73} INFO - Using connection ID 'user_api' for task execution.
[2023-04-30T00:23:16.951+0000] {http.py:170} ERROR - HTTP error: Internal Server Error
[2023-04-30T00:23:16.951+0000] {http.py:171} ERROR - <html>
<head>
<title>Uh oh, something bad happened</title>
</head>
<body align='center'>
<h1 align='center'>Uh oh, something bad happened</h1>
<a class="twitter-timeline" data-width="450" data-height="700" data-theme="light" href="https://twitter.com/randomapi">Tweets by randomapi</a> <script async src="//platform.twitter.com/widgets.js" charset="utf-8"></script>
</body>
</html>

[2023-04-30T00:23:16.963+0000] {taskinstance.py:1776} ERROR - Task failed with exception
Traceback (most recent call last):
  File "/home/airflow/.local/lib/python3.7/site-packages/airflow/providers/http/hooks/http.py", line 168, in check_response
    response.raise_for_status()
  File "/home/airflow/.local/lib/python3.7/site-packages/requests/models.py", line 1021, in raise_for_status
    raise HTTPError(http_error_msg, response=self)
requests.exceptions.HTTPError: 500 Server Error: Internal Server Error for url: https://randomuser.me/https://randomuser.me/

During handling of the above exception, another exception occurred:

Traceback (most recent call last):
  File "/home/airflow/.local/lib/python3.7/site-packages/airflow/sensors/base.py", line 199, in execute
    poke_return = self.poke(context)
  File "/home/airflow/.local/lib/python3.7/site-packages/airflow/providers/http/sensors/http.py", line 137, in poke
    raise exc
  File "/home/airflow/.local/lib/python3.7/site-packages/airflow/providers/http/sensors/http.py", line 128, in poke
    extra_options=self.extra_options,
  File "/home/airflow/.local/lib/python3.7/site-packages/airflow/providers/http/hooks/http.py", line 158, in run
    return self.run_and_check(session, prepped_request, extra_options)
  File "/home/airflow/.local/lib/python3.7/site-packages/airflow/providers/http/hooks/http.py", line 211, in run_and_check
    self.check_response(response)
  File "/home/airflow/.local/lib/python3.7/site-packages/airflow/providers/http/hooks/http.py", line 172, in check_response
    raise AirflowException(str(response.status_code) + ":" + response.reason)
airflow.exceptions.AirflowException: 500:Internal Server Error
[2023-04-30T00:23:16.969+0000] {taskinstance.py:1332} INFO - Marking task as FAILED. dag_id=user_processing, task_id=is_api_available, execution_date=20230429T000000, start_date=20230430T000003, end_date=20230430T002316
[2023-04-30T00:23:16.983+0000] {standard_task_runner.py:105} ERROR - Failed to execute job 272 for task is_api_available (500:Internal Server Error; 163098)
[2023-04-30T00:23:17.008+0000] {local_task_job.py:212} INFO - Task exited with return code 1
[2023-04-30T00:23:17.044+0000] {taskinstance.py:2596} INFO - 0 downstream tasks scheduled from follow-on schedule check
