[2023-04-26T00:00:02.962+0000] {taskinstance.py:1090} INFO - Dependencies all met for dep_context=non-requeueable deps ti=<TaskInstance: user_processing.is_api_available scheduled__2023-04-25T00:00:00+00:00 [queued]>
[2023-04-26T00:00:02.972+0000] {taskinstance.py:1090} INFO - Dependencies all met for dep_context=requeueable deps ti=<TaskInstance: user_processing.is_api_available scheduled__2023-04-25T00:00:00+00:00 [queued]>
[2023-04-26T00:00:02.972+0000] {taskinstance.py:1288} INFO - 
--------------------------------------------------------------------------------
[2023-04-26T00:00:02.973+0000] {taskinstance.py:1289} INFO - Starting attempt 1 of 1
[2023-04-26T00:00:02.973+0000] {taskinstance.py:1290} INFO - 
--------------------------------------------------------------------------------
[2023-04-26T00:00:02.988+0000] {taskinstance.py:1309} INFO - Executing <Task(HttpSensor): is_api_available> on 2023-04-25 00:00:00+00:00
[2023-04-26T00:00:02.994+0000] {standard_task_runner.py:55} INFO - Started process 1053871 to run task
[2023-04-26T00:00:02.997+0000] {standard_task_runner.py:82} INFO - Running: ['***', 'tasks', 'run', 'user_processing', 'is_api_available', 'scheduled__2023-04-25T00:00:00+00:00', '--job-id', '231', '--raw', '--subdir', 'DAGS_FOLDER/user_processing.py', '--cfg-path', '/tmp/tmpk7dbqr9e']
[2023-04-26T00:00:02.998+0000] {standard_task_runner.py:83} INFO - Job 231: Subtask is_api_available
[2023-04-26T00:00:03.065+0000] {task_command.py:389} INFO - Running <TaskInstance: user_processing.is_api_available scheduled__2023-04-25T00:00:00+00:00 [running]> on host 1f05588790e0
[2023-04-26T00:00:03.146+0000] {taskinstance.py:1518} INFO - Exporting the following env vars:
AIRFLOW_CTX_DAG_OWNER=***
AIRFLOW_CTX_DAG_ID=user_processing
AIRFLOW_CTX_TASK_ID=is_api_available
AIRFLOW_CTX_EXECUTION_DATE=2023-04-25T00:00:00+00:00
AIRFLOW_CTX_TRY_NUMBER=1
AIRFLOW_CTX_DAG_RUN_ID=scheduled__2023-04-25T00:00:00+00:00
[2023-04-26T00:00:03.149+0000] {http.py:122} INFO - Poking: https://randomuser.me/
[2023-04-26T00:00:03.159+0000] {base.py:73} INFO - Using connection ID 'user_api' for task execution.
[2023-04-26T00:00:03.829+0000] {http.py:170} ERROR - HTTP error: Internal Server Error
[2023-04-26T00:00:03.829+0000] {http.py:171} ERROR - <html>
<head>
<title>Uh oh, something bad happened</title>
</head>
<body align='center'>
<h1 align='center'>Uh oh, something bad happened</h1>
<a class="twitter-timeline" data-width="450" data-height="700" data-theme="light" href="https://twitter.com/randomapi">Tweets by randomapi</a> <script async src="//platform.twitter.com/widgets.js" charset="utf-8"></script>
</body>
</html>

[2023-04-26T00:00:03.842+0000] {taskinstance.py:1776} ERROR - Task failed with exception
Traceback (most recent call last):
  File "/home/airflow/.local/lib/python3.7/site-packages/airflow/providers/http/hooks/http.py", line 168, in check_response
    response.raise_for_status()
  File "/home/airflow/.local/lib/python3.7/site-packages/requests/models.py", line 1021, in raise_for_status
    raise HTTPError(http_error_msg, response=self)
requests.exceptions.HTTPError: 500 Server Error: Internal Server Error for url: https://randomuser.me/https://randomuser.me/

During handling of the above exception, another exception occurred:

Traceback (most recent call last):
  File "/home/airflow/.local/lib/python3.7/site-packages/airflow/sensors/base.py", line 199, in execute
    poke_return = self.poke(context)
  File "/home/airflow/.local/lib/python3.7/site-packages/airflow/providers/http/sensors/http.py", line 137, in poke
    raise exc
  File "/home/airflow/.local/lib/python3.7/site-packages/airflow/providers/http/sensors/http.py", line 128, in poke
    extra_options=self.extra_options,
  File "/home/airflow/.local/lib/python3.7/site-packages/airflow/providers/http/hooks/http.py", line 158, in run
    return self.run_and_check(session, prepped_request, extra_options)
  File "/home/airflow/.local/lib/python3.7/site-packages/airflow/providers/http/hooks/http.py", line 211, in run_and_check
    self.check_response(response)
  File "/home/airflow/.local/lib/python3.7/site-packages/airflow/providers/http/hooks/http.py", line 172, in check_response
    raise AirflowException(str(response.status_code) + ":" + response.reason)
airflow.exceptions.AirflowException: 500:Internal Server Error
[2023-04-26T00:00:03.846+0000] {taskinstance.py:1332} INFO - Marking task as FAILED. dag_id=user_processing, task_id=is_api_available, execution_date=20230425T000000, start_date=20230426T000002, end_date=20230426T000003
[2023-04-26T00:00:03.859+0000] {standard_task_runner.py:105} ERROR - Failed to execute job 231 for task is_api_available (500:Internal Server Error; 1053871)
[2023-04-26T00:00:03.891+0000] {local_task_job.py:212} INFO - Task exited with return code 1
[2023-04-26T00:00:03.927+0000] {taskinstance.py:2596} INFO - 0 downstream tasks scheduled from follow-on schedule check
